Traceback (most recent call last):
  File "/Users/pcchen/miniforge3/lib/python3.10/site-packages/jupyter_cache/executors/utils.py", line 58, in single_nb_execution
    executenb(
  File "/Users/pcchen/miniforge3/lib/python3.10/site-packages/nbclient/client.py", line 1314, in execute
    return NotebookClient(nb=nb, resources=resources, km=km, **kwargs).execute()
  File "/Users/pcchen/miniforge3/lib/python3.10/site-packages/jupyter_core/utils/__init__.py", line 165, in wrapped
    return loop.run_until_complete(inner)
  File "/Users/pcchen/miniforge3/lib/python3.10/asyncio/base_events.py", line 649, in run_until_complete
    return future.result()
  File "/Users/pcchen/miniforge3/lib/python3.10/site-packages/nbclient/client.py", line 709, in async_execute
    await self.async_execute_cell(
  File "/Users/pcchen/miniforge3/lib/python3.10/site-packages/nbclient/client.py", line 1062, in async_execute_cell
    await self._check_raise_for_error(cell, cell_index, exec_reply)
  File "/Users/pcchen/miniforge3/lib/python3.10/site-packages/nbclient/client.py", line 918, in _check_raise_for_error
    raise CellExecutionError.from_cell_and_msg(cell, exec_reply_content)
nbclient.exceptions.CellExecutionError: An error occurred while executing the following cell:
------------------
A2 = A[:,2].reshape(2,1).set_rowrank(1)
print("rowrank={}".format(A.rowrank()))
print(A2.shape())
A2.print_diagram()
print("2-th column\n", A[:,2]) # 2-th column
------------------


[0;31m---------------------------------------------------------------------------[0m
[0;31mRuntimeError[0m                              Traceback (most recent call last)
Cell [0;32mIn[7], line 1[0m
[0;32m----> 1[0m A2 [38;5;241m=[39m [43mA[49m[43m[[49m[43m:[49m[43m,[49m[38;5;241;43m2[39;49m[43m][49m[38;5;241;43m.[39;49m[43mreshape[49m[43m([49m[38;5;241;43m2[39;49m[43m,[49m[38;5;241;43m1[39;49m[43m)[49m[38;5;241m.[39mset_rowrank([38;5;241m1[39m)
[1;32m      2[0m [38;5;28mprint[39m([38;5;124m"[39m[38;5;124mrowrank=[39m[38;5;132;01m{}[39;00m[38;5;124m"[39m[38;5;241m.[39mformat(A[38;5;241m.[39mrowrank()))
[1;32m      3[0m [38;5;28mprint[39m(A2[38;5;241m.[39mshape())

[0;31mRuntimeError[0m: 
# Cytnx error occur at void cytnx::Tensor_impl::reshape_(const std::vector<long long int>&)
# error: [ERROR] new shape does not match the number of elements.
# file : /Users/pcchen/github/Cytnx/include/backend/Tensor_impl.hpp (289)

